<mujoco model="ur3e">
  <compiler angle="radian" meshdir="assets" autolimits="true"/>

  <option integrator="implicitfast"/>

  <default>
    <default class="ur3e">
      <material specular="0.5" shininess="0.25"/>
      <joint axis="0 1 0" range="-6.28319 6.28319" armature="0.1"/>
      <general gaintype="fixed" biastype="affine" ctrlrange="-6.2831 6.2831"/>
      <default class="size2">
        <general  gainprm="1000" biasprm="0 -1000 -200" forcerange="-56 56"/>
      </default>
      <default class="size1">
        <default class="size1_limited">
          <joint range="-3.14159 3.14159"/>
          <general gainprm="500" biasprm="0 -500 -100" ctrlrange="-3.14159 3.14159" forcerange="-28 28"/>
        </default>
      </default>
      <default class="size0">
        <general gainprm="200" biasprm="0 -200 -40" forcerange="-12 12"/>
      </default>
      <default class="visual">
        <geom type="mesh" contype="0" conaffinity="0" group="2"/>
      </default>
      <default class="collision">
        <geom type="capsule" group="3"/>
        <default class="eef_collision">
          <geom type="cylinder"/>
        </default>
      </default>
      <site size="0.001" rgba="0.5 0.5 0.5 0.3" group="4"/>
    </default>

        <default class="2f140">
      <mesh scale="0.001 0.001 0.001"/>
      <general biastype="affine"/>

      <joint axis="0 1 0"/>
      <default class="driver">
        <joint range="0 0.8" armature="0.005" damping="0.1" solimplimit="0.95 0.99 0.001" solreflimit="0.005 1"/>
      </default>
      <default class="follower">
        <joint range="-0.872664 0.872664"  solimplimit="0.95 0.99 0.001" solreflimit="0.005 1"/>
      </default>
      <default class="spring_link">
        <joint range="-0.29670597283 0.8" stiffness="0.05 " springref="2.8" damping="0.125"/>
      </default>
      <default class="coupler">
        <joint range="-1.57 1.57" solimplimit="0.95 0.99 0.001" solreflimit="0.005 1"/>
      </default>

      <default class="visual_gripper">
        <geom type="mesh" contype="0" conaffinity="0" group="2"/>
      </default>
      <default class="collision_gripper">
        <geom type="mesh" group="3"/>
        <default class="pad_box1">
          <geom mass="0" type="box" pos="0 -0.0026 0.028125" size="0.011 0.004 0.009375" friction="0.7"
            solimp="0.95 0.99 0.001" solref="0.004 1" priority="1" rgba="0.55 0.55 0.55 1"/>
        </default>
        <default class="pad_box2">
          <geom mass="0" type="box" pos="0 -0.0026 0.009375" size="0.011 0.004 0.009375" friction="0.6"
            solimp="0.95 0.99 0.001" solref="0.004 1" priority="1" rgba="0.45 0.45 0.45 1"/>
        </default>
      </default>
    </default>

  </default>
  
  <asset>
    <material class="ur3e" name="black" rgba="0.033 0.033 0.033 1"/>
    <material class="ur3e" name="jointgray" rgba="0.278 0.278 0.278 1"/>
    <material class="ur3e" name="linkgray" rgba="0.82 0.82 0.82 1"/>
    <material class="ur3e" name="urblue" rgba="0.49 0.678 0.8 1"/>

    <mesh file="base_0.obj"/>
    <mesh file="base_1.obj"/>
    <mesh file="shoulder_0.obj"/>
    <mesh file="shoulder_1.obj"/>
    <mesh file="shoulder_2.obj"/>
    <mesh file="upperarm_0.obj"/>
    <mesh file="upperarm_1.obj"/>
    <mesh file="upperarm_2.obj"/>
    <mesh file="upperarm_3.obj"/>
    <mesh file="forearm_0.obj"/>
    <mesh file="forearm_1.obj"/>
    <mesh file="forearm_2.obj"/>
    <mesh file="forearm_3.obj"/>
    <mesh file="wrist1_0.obj"/>
    <mesh file="wrist1_1.obj"/>
    <mesh file="wrist1_2.obj"/>
    <mesh file="wrist2_0.obj"/>
    <mesh file="wrist2_1.obj"/>
    <mesh file="wrist2_2.obj"/>
    <mesh file="wrist3.obj"/>


        <!-- gripper -->
    <material name="metal" specular="0.5" shininess="0.25" rgba="0.58 0.58 0.58 1"/>
    <material name="silicone" specular="0.5" shininess="0.25" rgba="0.1882 0.1882 0.1882 1"/>
    <material name="gray" specular="0.5" shininess="0.25" rgba="0.4627 0.4627 0.4627 1"/>

    <mesh class="2f140" name="base_mount" file="base_mount_zeroed.obj"/>
    <mesh class="2f140" name="base" file="base_zeroed.obj"/>
    <mesh class="2f140" name="driver" file="driver_zeroed.obj"/>
    <mesh class="2f140" name="coupler" file="coupler_zeroed.obj"/>
    <mesh class="2f140" name="follower" file="follower_zeroed.obj"/>
    <mesh class="2f140" name="pad" file="pad_zeroed.obj"/>
    <mesh class="2f140" name="spring_link" file="spring_link_zeroed.obj"/>

  </asset>

  <worldbody>
    <light name="spotlight" mode="targetbodycom" target="wrist_3_link" pos="0 -1 2"/>
    <body name="base" childclass="ur3e">
      <inertial mass="2" pos="0 0 0" diaginertia="0.0030532 0.0030532 0.005625"/>
      <geom mesh="base_0" material="jointgray" class="visual"/>
      <geom mesh="base_1" material="black" class="visual"/>
      <body name="shoulder_link" pos="0 0 0.152">
        <inertial mass="2" pos="0 0 0" diaginertia="0.00809316 0.00809316 0.005625"/>
        <joint name="shoulder_pan_joint" class="size2" axis="0 0 1"/>
        <geom mesh="shoulder_0" material="urblue" class="visual"/>
        <geom mesh="shoulder_1" material="black" class="visual"/>
        <geom mesh="shoulder_2" material="jointgray" class="visual"/>
        <geom class="collision" size="0.047 0.05" pos="0 0 -0.032"/>
        <body name="upper_arm_link" pos="0 0.12 0" quat="1 0 1 0">
          <inertial mass="3.42" pos="0 0 0.122" diaginertia="0.0217285 0.0217285 0.00961875"/>
          <joint name="shoulder_lift_joint" class="size2"/>
          <geom mesh="upperarm_0" material="black" class="visual"/>
          <geom mesh="upperarm_1" material="urblue" class="visual"/>
          <geom mesh="upperarm_2" material="jointgray" class="visual"/>
          <geom mesh="upperarm_3" material="linkgray" class="visual"/>
          <geom class="collision" size="0.046 0.06" pos="0 -0.04 0" quat="1 1 0 0"/>
          <geom class="collision" size="0.038 0.11" pos="0 0 0.12"/>
          <body name="forearm_link" pos="0 -0.093 0.244">
            <inertial mass="1.26" pos="0 0 0.10625" diaginertia="0.00654457 0.00654457 0.00354375"/>
            <joint name="elbow_joint" class="size1_limited"/>
            <geom mesh="forearm_0" material="urblue" class="visual"/>
            <geom mesh="forearm_1" material="linkgray" class="visual"/>
            <geom mesh="forearm_2" material="black" class="visual"/>
            <geom mesh="forearm_3" material="jointgray" class="visual"/>
            <geom class="collision" size="0.038 0.048" pos="0 0.062 0" quat="1 1 0 0"/>
            <geom class="collision" size="0.032 0.103" pos="0 0 0.11"/>
            <body name="wrist_1_link" pos="0.0005 0 0.2125" quat="1 0 1 0">
              <inertial mass="0.8" pos="0 0.104 0" diaginertia="0.00225 0.002085 0.002085"/>
              <joint name="wrist_1_joint" class="size0"/>
              <geom mesh="wrist1_0" material="jointgray" class="visual"/>
              <geom mesh="wrist1_1" material="urblue" class="visual"/>
              <geom mesh="wrist1_2" material="black" class="visual"/>
              <geom class="collision" size="0.032 0.05" pos="0 0.045 0" quat="1 1 0 0"/>
              <body name="wrist_2_link" pos="0 0.104 0">
                <inertial mass="0.8" pos="0 0 0.085" diaginertia="0.00225 0.002085 0.002085"/>
                <joint name="wrist_2_joint" axis="0 0 1"/>
                <geom mesh="wrist2_0" material="jointgray" class="visual"/>
                <geom mesh="wrist2_1" material="black" class="visual"/>
                <geom mesh="wrist2_2" material="urblue" class="visual"/>
                <geom class="collision" size="0.032 0.05" pos="0 0 0.035"/>
                <geom class="collision" size="0.032 0.027" pos="0 0.01 0.085" quat="1 1 0 0"/>
                <body name="wrist_3_link" pos="0 0 0.085">
                  <inertial mass="0.35" pos="0 0.0715 0" quat="1 0 0 1" diaginertia="0.0001792 0.000136267 0.000136267"/>
                  <joint name="wrist_3_joint"/>
                  <geom mesh="wrist3" material="linkgray" class="visual"/>
                  <geom class="eef_collision" size="0.032 0.023" pos="0 0.07 0" quat="1 1 0 0"/>
                  <site name="attachment_site" pos="0 0.09215 0" quat="-1 1 0 0"/>
                </body>

                   <body name="base_mount" pos="0 0.1 0.085" quat="0.7071 -0.7071 0 0" childclass="2f140">
                    <geom class="visual_gripper" mesh="base_mount" material="black"/>
                    <body name="base_gripper" pos="0 0 0.0038" quat="1 0 0 0">
                    <geom class="visual_gripper" mesh="base" material="black"/>
                    <geom class="collision_gripper" mesh="base"/>
                    <site name="pinch" pos="0 0 0.145" type="sphere" group="5" rgba="0.9 0.9 0.9 1" size="0.005"/>
        
                    <!-- Right-hand side 4-bar linkage -->
                    <!-- driver -->
                    <body name="right_driver" pos=" -0.030601 0 0.054905">
                      <joint name="right_driver_joint" class="driver" pos="0 0 0"/>
                      <geom name="right_driver" class="visual" mesh="driver" material="gray"/>
                      <geom class="collision_gripper" mesh="driver"/>

                      <!-- coupler -->
                        <body name="right_coupler" pos="-0.0315300 0 -0.003733">
                        <!-- <joint name="right_coupler_joint" class="coupler" pos="0 0 0"/> -->
                        <geom name="right_coupler" class="visual_gripper" mesh="coupler" material="black"/>
                        <geom class="collision_gripper" mesh="coupler"/>
                
                            <!-- follower -->
                            <body name="right_follower" pos="-0.015514 0 0.086289">
                                <joint name="right_follower_joint" class="follower"  pos="-0.017901 0 -0.006515"/>
                                <geom name="right_follower" class="visual_gripper" mesh="follower" material="black"/>
                                <geom class="collision_gripper" mesh="follower"/>
                        
                                <!-- pad -->
                                <body name="right_pad" pos="-0.0066 0 0.00625">
                                    <geom name="right_pad" class="visual_gripper" mesh="pad"/>                
                                    <geom class="collision_gripper" mesh="pad"/>  
                                </body>
                            </body>    
                      </body>
                    </body>
                    <!-- spring -->
                    <body name="right_spring_link" pos="-0.012700 0 0.061420">
                      <joint name="right_spring_link_joint" class="spring_link" pos="0 0 0"/>
                      <geom name="right_spring_link" class="visual_gripper" mesh="spring_link" material="black"/>
                      <geom class="collision_gripper" mesh="spring_link"/>
                    </body>

                    <!-- left-hand side 4-bar linkage -->
                    <!-- driver -->
                    <body name="left_driver" pos=" 0.030601 0 0.054905" quat="0 0 0 1">
                      <joint name="left_driver_joint" class="driver" pos="0 0 0" axis="0 1 0"  />
                      <geom name="left_driver" class="visual_gripper" mesh="driver" material="gray" quat="1 0 0 0"/>
                      <geom class="collision_gripper" mesh="driver"/>

                      <!-- coupler -->
                      <body name="left_coupler" pos="-0.0315300 0 -0.003733" quat="1 0 0 0">
                        <!-- <joint name="left_coupler_joint" class="coupler" pos="0 0 0" axis="0 1 0"/> -->
                        <geom name="left_coupler" class="visual_gripper" mesh="coupler" material="black" quat="1 0 0 0"/>
                        <geom class="collision_gripper" mesh="coupler"/>

                        <!-- follower -->
                        <body name="left_follower" pos="-0.015514 0 0.086289" quat="1 0 0 0">
                            <joint name="left_follower_joint" class="follower"  pos="-0.017901 0 -0.006515" axis="0 1 0"/>
                            <geom name="left_follower" class="visual_gripper" mesh="follower" material="black" quat="1 0 0 0"/>
                            <geom class="collision_gripper" mesh="follower"/>
                        
                            <body name="left_pad" pos="-0.0066 0 0.00625" quat="1 0 0 0">
                                <geom name="left_pad" class="visual_gripper" mesh="pad" quat="1 0 0 0"/>  
                                <geom class="collision_gripper" mesh="pad"/>              
                            </body>
                      </body>
                
                      </body>
                    </body>
                    <!-- spring -->
                    <body name="left_spring_link" pos="0.012700 0 0.061420" quat="0 0 0 1">
                      <joint name="left_spring_link_joint" class="spring_link" pos="0 0 0" axis="0 1 0"/>
                      <geom name="left_spring_link" class="visual_gripper" mesh="spring_link" material="black" quat="1 0 0 0"/>
                      <geom class="collision_gripper" mesh="spring_link"/>
                    </body>

                  </body>
                </body>
              </body>
            </body>
          </body>
        </body>
      </body>
    </body>
  </worldbody>

  <actuator>
    <general class="size2" name="shoulder_pan" joint="shoulder_pan_joint"/>
    <general class="size2" name="shoulder_lift" joint="shoulder_lift_joint"/>
    <general class="size1_limited" name="elbow" joint="elbow_joint"/>
    <general class="size0" name="wrist_1" joint="wrist_1_joint"/>
    <general class="size0" name="wrist_2" joint="wrist_2_joint"/>
    <general class="size0" name="wrist_3" joint="wrist_3_joint"/>
    <general class="2f140" name="fingers_actuator" tendon="split" forcerange="-5 5" ctrlrange="0 255" gainprm="0.3137255 0 0" biasprm="0 -100 -10"/>
  </actuator>

    <!-- gripper tendon -->
  <tendon>
    <fixed name="split">
      <joint joint="right_driver_joint" coef="0.5"/>
      <joint joint="left_driver_joint" coef="0.5"/>
    </fixed>
  </tendon>
  <!--gripper anchors for closed linkage -->
  <equality>
    <connect anchor="-0.0 0 0.0" body1="right_follower" body2="right_spring_link" solimp="0.95 0.99 0.001" solref="0.005 1" active="true"/>
    <connect anchor="-0.0 0 0.0" body1="left_follower" body2="left_spring_link" solimp="0.95 0.99 0.001" solref="0.005 1" active="true"/>
    <joint joint1="right_driver_joint" joint2="left_driver_joint" polycoef="0 1 0 0 0" solimp="0.95 0.99 0.001" solref="0.005 1"/>
  </equality>

  <keyframe>
    <key name="home" qpos="-1.5708 -1.5708 1.5708 -1.5708 -1.5708 0 0 0 0 0 0 0"
        ctrl="-1.5708 -1.5708 1.5708 -1.5708 -1.5708 0 0"/>
  </keyframe>
</mujoco>
